Workbook

Sheet Final_draft
X1: name (to be refine) | Y1: Key toxicological data summary | Z1: Mutagenicity Ames details experimental | AA1: Mutagenicity Ames details predictions | AB1: NOAEL details + final call | AC1: Gene mutation (other endpoints) | AD1: Genotoxicity (Clastogenicity/aneugenicity) | AE1: DART | AF1: Endocrine | AG1: LOAEL details | AJ1: TD50 | AK1: UFs + sBHGV | AM1: NOAEL details + (N)LOAEL final call
X2: N.columns | Y2: 30 | Z2: 21 | AA2: 21 | AB2: 43 | AC2: 7 | AD2: 19 | AE2: 7 | AF2: 29 | AJ2: 10 | EQ2: all values are in mg/kg bw/day | GJ2: 0.15 | GK2: 0.08 | GL2: 0.05 | GN2: 0.02
J3: Available evaluations | M3: Genotoxicity EFSA final call | O3: EXPERIMENTAL Ames Mutagenicity | AJ3: PREDICTION Ames Mutagenicity | BF3: (Ames) Mutagenicity final call | BK3: Experimental Micronucleus (MN) | BU3: Prediction Micronucleus (MN) | CC3: Experimental Mouse Lymphoma | CF3: Prediction Mouse Lymphoma | CJ3: Experimental Chromosomal Aberration (CA) | CW3: Prediction Chromosomal Aberration (CA) | DC3: Experimental other genotoxicity endpoint | DL3: Prediction other genotoxicity endpoint | DQ3: Experimental TD50 (mg/kg bw/day) | DS3: Prediction TD50 (mg/kg bw/day) | EA3: Experimental NOAEL (mg/kg bw/day) | EM3: Experimental LOAEL (mg/kg bw/day) | FA3: Predicted NOAEL (mg/kg bw/day) | FH3: Predicted LOAEL (mg/kg bw/day) | FP3: (N)LOAEL final call | FU3: UFs | GA3: Cramer Class | GC3: TTC | GE3: (s)HBGV | GI3: chemical-specific SBL (mg/kg) | GN3: TTC-derived-SBL (mg/kg) | GS3: DART experimental | GU3: DART prediction | GZ3: ER/AR experimental | HE3: ER/AR prediction | HL3: Thyroid receptor Experimental | HO3: Thyroid receptor prediction | HS3: Experimental Aromatase activity | HU3: Prediction Aromatase activity | HY3: Experimental Endocrine disruptor activity | IA3: Prediction Endocrine disruptor activity
M4: EFSA OFT | O4: VEGA databases | W4: Leadscope databases | AD4: Other data sources | AJ4: VEGA Consensus & single models | AU4: Leadscope Bacterial Consensus & single models | BB4: Leadscope Ames additional models | BK4: in vitro MN | BO4: in vivo MN | BU4: in vitro MN | BW4: in vivo MN | CC4: in vitro | CF4: in vitro | CJ4: in vitro CA | CP4: in vivo CA | CW4: in vitro CA | CZ4: in vivo CA | DC4: in vitro | DF4: in vivo | DL4: in vitro | DO4: in vivo | EA4: (Q)SAR models' database subchronic toxicity | ED4: EFSA OFT db | EG4: OECD QSAR Toolbox | EM4: (Q)SAR models' database (sub)chronic toxicity | EQ4: EFSA OFT db | EU4: OECD QSAR Toolbox | FC4: subchronic | FH4: (sub)chronic
A5: CAS number | B5: Nestle ID code | C5: SMILES (original) | D5: SMILES (neutralized) | E5: Reliability (neutralized) | F5: SMILES (VEGA CDK) | G5: Duplicate (VEGA CDK) | H5: Reliability (VEGA CDK) | I5: Chemical name | J5: CFSG/CRA ref no | K5: "manually generated" SBL (Y/N) | L5: Expert review | M5: Call | N5: doi | O5: CAESAR | P5: Reliability | Q5: SarPy | R5: Reliability | S5: ISS | T5: Reliability | U5: KNN | V5: Reliability | W5: Bacterial Mutation Alerts | X5: Bacterial Mutation | Y5: Reliability | Z5: Salmonella Mut | AA5: Reliability | AB5: E Coli-Sal 102A-T Mut | AC5: Reliability | AD5: ECHA REACH db (OECD QSAR Toolbox) | AE5: Reliability | AF5: ICE dataset (nih.gov) | AG5: Reliability | AH5: ECVAM | AI5: Reliability | AJ5: Consensus | AK5: Mutagenic score | AL5: Non-Mutagenic Score | AM5: CAESAR | AN5: Reliability | AO5: SarPy | AP5: Reliability | AQ5: ISS | AR5: Reliability | AS5: KNN | AT5: Reliability | AU5: Bacterial Mutation Consensus | AV5: Reliability | AW5: Bacterial Mutation Alerts | AX5: Bacterial Mutation Alerts identified | AY5: Bacterial Mutation | AZ5: Bacterial Mutation Probability | BA5: Reliability | BB5: Salmonella Mut | BC5: Salmonella Mut Positive Prediction Probability | BD5: E Coli-Sal 102A-T Mut | BE5: E Coli - Sal 102 A-T Mut Positive Prediction Probability | BF5: Final call | BG5: Reliability VEGA | BH5: Exp/pred | BI5: Source | BJ5: Remarks | BK5: ECHA REACH db (OECD QSAR Toolbox ) | BL5: ECVAM | BM5: VEGA (IRFMN-VERMEER) | BN5: Remarks | BO5: LS | BP5: ECVAM | BQ5: ICE | BR5: ECHA REACH db (OECD QSAR Toolbox ) | BS5: VEGA (IRFMN) | BT5: Remarks | BU5: VEGA (IRFMN-VERMEER) | BV5: Reliability | BW5: VEGA (IRFMN) | BX5: Reliability and Consensus status | BY5: LS In Vivo Micronuc Mouse | BZ5: In Vivo Micronuc Mouse Positive Prediction Probability | CA5: Toxtree Structure Alerts in vivo MN in rodents | CB5: Remarks | CC5: LS Mouse Lymphoma Act Experimental Value | CD5: LS Mouse Lymphoma Unact Experimental Value | CE5: Remarks | CF5: LS Mouse Lymphoma Act Prediction | CG5: LS Mouse Lymphoma ActPositive Prediction Probability | CH5: LS Mouse Lymphoma Unact v2 Prediction | CI5: LS Mouse Lymphoma Unact v2 Positive Prediction Probability | CJ5: ECHA REACH db (OECD QSAR Toolbox ) | CK5: LS In Vitro Chrom Ab CHO v2 | CL5: LS In Vitro Chrom Ab CHL v2 | CM5: VEGA Chromosomal aberration model (CORAL) | CN5: ECVAM | CO5: Remarks | CP5: LS chrom ab(A7P) | CQ5: LS chrom ab other rodent(A7R) | CR5: LS chrom ab rat (A7Q) | CS5: ECVAM | CT5: ICE | CU5: ECHA REACH db (OECD QSAR Toolbox) | CV5: Remarks | CW5: LS In Vitro Chrom Ab CHO | CX5: LS In Vitro Chrom Ab CHL | CY5: VEGA Chromosomal aberration model (CORAL) | CZ5: LS chrom ab(A7P) | DA5: LS chrom ab other rodent(A7R) | DB5: LS chrom ab rat (A7Q) | DC5: LS In Vitro SCE CHO | DD5: LS In Vitro SCE Comp | DE5: LS SCE in vitro other (A8I) | DF5: LS In Vivo Rodent Mut Experimental Value | DG5: LS In Vivo Rodent DL Mut | DH5: ECVAM TGR Overall | DI5: ECVAM in vivo UDS Overall | DJ5: in vivo DNA damage Overall | DK5: Remarks | DL5: LS In Vitro SCE CHO | DM5: LS In Vitro SCE Comp | DN5: LS SCE in vitro other (A8I) | DO5: LS In Vivo Rodent Mut | DP5: LS In Vivo Rodent DL Mut | DQ5: CPDB rat | DR5: CPDB mouse | DS5: ADMET rat | DT5: AD info | DU5: ADMET mouse | DV5: AD info | DW5: Lazar rat | DX5: AD info | DY5: Lazar mouse | DZ5: AD info | EA5: VEGA NOAEL (IRFMN-CORAL) | EB5: VEGA Liver NOAEL (CORAL) | EC5: CORAL Gadaleta 2021 (confidential) | ED5: EFSA human | EE5: EFSA animal | EF5: Chronic/Subchronic/devtox | EG5: EFSA ToolBox | EH5: Chronic/Subchronic/devtox | EI5: Munro Toolbox | EJ5: Chronic/Subchronic/devtox | EK5: ECHA | EL5: Chronic/Subchronic/devtox | EM5: VEGA Liver LOAEL (CORAL) | EN5: Helma 2018 | EO5: Mazzatorta 2008 | EP5: CORAL Gadaleta 2021 (confidential) | EQ5: EFSA human | ER5: Chronic/Subchronic/devtox | ES5: EFSA animal | ET5: Chronic/Subchronic/devtox | EU5: EFSA ToolBox | EV5: Chronic/Subchronic/devtox | EW5: Munro Toolbox | EX5: Chronic/Subchronic/devtox | EY5: ECHA | EZ5: Chronic/Subchronic/devtox | FA5: VEGA NOAEL (IRFMN-CORAL) | FB5: Reliability | FC5: VEGA Liver NOAEL (CORAL) | FD5: Reliability | FE5: Gadaleta 2021 NOAEL | FF5: AD info | FG5: Reliability | FH5: VEGA Liver LOAEL (CORAL) | FI5: Reliability | FJ5: Helma 2018 | FK5: AD info | FL5: Mazzatorta 2008 | FM5: Gadaleta 2021 LOAEL | FN5: AD info | FO5: Reliability | FP5: Min (N)LOAEL | FQ5: Source | FR5: "internal" reliability | FS5: Exp/pred | FT5: Remarks | FU5: Subchronic-to-Chronic (UF=2) | FV5: Inter-species (UF=10) | FW5: Intra-species (UF=10) | FX5: LOAEL to NOAEL (UF=10) | FY5: DB UF (3-10) | FZ5: SF applied | GA5: Cramer Class | GB5: Cramer Class with Extension | GC5: TTC value (ug /kg bw/d) | GD5: TTC-source | GE5: HBGV EFSA OFT | GF5: sHBGV | GG5: HBGV | GH5: HBGV | GI5: SBL1 | GJ5: SBL2 | GK5: SBL3 | GL5: SBL4 | GM5: chemical-specific-SBL remarks | GN5: SBL1 | GO5: SBL2 | GP5: SBL3 | GQ5: SBL4 | GR5: TTC-derived-SBL remarks | GS5: VEGA-Developmental Toxicity model (CAESAR) | GT5: VEGA-Developmental/Reproductive Toxicity library (PG) | GU5: VEGA-Developmental Toxicity model (CAESAR) | GV5: Reliability | GW5: VEGA-Developmental/Reproductive Toxicity library (PG) | GX5: Reliability | GY5: P&G DART scheme QSAR Toolbox | GZ5: Estrogen Receptor-mediated effect (IRFMN-CERAPP) | HA5: Estrogen Receptor Relative Binding Affinity model (IRFMN) | HB5: Androgen Receptor-mediated effect (IRFMN-COMPARA) | HC5: other | HD5: source | HE5: Estrogen Receptor-mediated effect (IRFMN-CERAPP) | HF5: Reliability | HG5: Estrogen Receptor Relative Binding Affinity model (IRFMN) | HH5: Reliability | HI5: Androgen Receptor-mediated effect (IRFMN-COMPARA) | HJ5: Reliability | HK5: Estrogen Receptor Binding QSAR Toolbox | HL5: VEGA-Thyroid receptor alpha effect | HM5: VEGA-Thyroid receptor beta effect | HN5: Other | HO5: VEGA-Thyroid receptor alpha effect | HP5: Reliability | HQ5: VEGA-Thyroid receptor beta effect | HR5: Reliability | HS5: VEGA-Aromatase activity model (IRFMN) | HT5: VEGA-Aromatase activity model (TOX21) | HU5: VEGA-Aromatase activity model (IRFMN) | HV5: Reliability | HW5: VEGA-Aromatase activity model (TOX21) | HX5: Reliability | HY5: VEGA-Endocrine disruptor activity screening (IRFMN) | HZ5: Reliability | IA5: VEGA-Endocrine disruptor activity screening (IRFMN) | IB5: Reliability | IC5: SBL 1 | ID5: SBL 2 | IE5: SBL 3 | IF5: SBL 4 | IH5: SBL TO BE CHECKED
A6: 110-82-7 | B6: N-00001 | C6: C1CCCCC1 | F6: C1CCCCC1 | I6: Cyclohexane | M6: Negative | U6: NON-Mutagenic | W6: Negative | X6: Negative | Z6: Negative | AD6: Negative, | AF6: Negative, | AJ6: NON-Mutagenic | AK6: 0 | AL6: 1 | AM6: NON-Mutagenic | AN6: GOOD | AO6: Possible NON-Mutagenic | AP6: GOOD | AQ6: NON-Mutagenic | AR6: MODERATE | AS6: NON-Mutagenic | AU6: Negative | AW6: Negative | AX6: [No Alerts] | AY6: Negative | AZ6: 0.341 | BB6: Negative | BC6: 0.221 | BD6: Not In Domain | BE6: 0.157 | BF6: Negative | BH6: Experimental | BI6: VEGA, Leadscope, ECHA REACH, ICE | BU6: Inactive | BV6: GOOD | BW6: NON-genotoxic | BX6: MODERATE-Predictions NOT in agreement | BY6: Not In Domain | BZ6: 0.618 | CA6: No alerts for the micronucleus assay (Class II) | CC6: Negative | CD6: Negative | CF6: Negative | CG6: 0.468 | CH6: Negative | CI6: 0.517 | CL6: Negative | CM6: Inactive | CP6: Negative | CR6: Negative | CW6: Not In Domain | CX6: Negative | CY6: Inactive | CZ6: Negative | DA6: Not In Domain | DB6: Negative | DC6: Negative | DD6: Negative | DL6: Negative | DM6: Negative | DN6: Not In Domain | DO6: Not In Domain | DP6: Not In Domain | DS6: 402.727 | DU6: 173.493 | DX6: no | DZ6: no | FA6: 35.34 | FB6: MODERATE | FC6: 195.07427 | FD6: LOW | FE6: 47.141131 | FF6: YES | FH6: 95.984255 | FI6: LOW | FJ6: 83.5 | FK6: maybe | FL6: 51.3 | FM6: 196.24563 | FN6: YES | FP6: 5.13 | FQ6: Mazzatorta | FS6: PRED | FU6: 1 | FV6: 10 | FW6: 10 | FX6: 10 | FY6: 3 | FZ6: =FU6*FV6*FW6*FX6*FY6 -> 3000 | GA6: Low (Class I) | GB6: Low (Class I) | GC6: 30 | GD6: ToxTree, Nestlé Lazar, QSAR ToolBox v 4.4 | GF6: 0.0171 | GU6: NON-Toxicant | GV6: LOW | GW6: NON-Toxicant | GX6: LOW | GY6: Not known precedent reproductive and developmental toxic potential | HE6: Not predicted | HF6: LOW | HG6: Inactive | HH6: MODERATE | HI6: NON-active | HJ6: GOOD | HK6: Non binder, without OH or NH2 group | HL6: Inactive | HM6: Inactive | HO6: Inactive | HP6: EXPERIMENTAL | HQ6: Inactive | HR6: EXPERIMENTAL | HU6: Inactive | HV6: GOOD | HW6: Not predicted | HX6: LOW | IA6: Inactive | IB6: [Model ]Unable to perform Applicability Domain check. | IH6: no
A7: 110-54-3 | B7: N-00002 | C7: CCCCCC | F7: CCCCCC | I7: n-Hexane | M7: Negative | O7: NON-Mutagenic | Q7: NON-Mutagenic | U7: NON-Mutagenic | W7: Negative | X7: Negative | Z7: Negative | AD7: Negative, | AF7: Negative, | AJ7: NON-Mutagenic | AK7: 0 | AL7: 1 | AM7: NON-Mutagenic | AN7: EXPERIMENTAL | AO7: Possible NON-Mutagenic | AQ7: NON-Mutagenic | AR7: MODERATE | AS7: NON-Mutagenic | AU7: Negative | AW7: Negative | AX7: [No Alerts] | AY7: Negative | AZ7: 0.149 | BB7: Negative | BC7: 0.0751 | BD7: Not In Domain | BE7: 0.167 | BF7: Negative | BH7: Experimental | BI7: VEGA, Leadscope, ECHA REACH, ICE | BO7: Negative | BQ7: Negative, | BS7: NON-genotoxic | BU7: Inactive | BV7: GOOD | BW7: NON-genotoxic | BX7: EXPERIMENTAL-Both predictions in agreement | BY7: Negative | BZ7: 0.371 | CA7: No alerts for the micronucleus assay (Class II) | CF7: Not In Domain | CG7: 0.327 | CH7: Not In Domain | CI7: 0.42 | CK7: Negative | CM7: Inactive | CP7: Positive | CQ7: Positive | CW7: Negative | CX7: Not In Domain | CY7: Inactive | CZ7: Positive | DA7: Positive | DB7: Not In Domain | DC7: Positive | DD7: Positive | DL7: Positive | DM7: Positive | DN7: Not In Domain | DO7: Not In Domain | DP7: Not In Domain | DQ7: I | DR7: 30300 | DS7: 114.884 | DU7: 166.248 | DW7: 6.39 | DX7: maybe | DY7: 77.9 | DZ7: maybe | EK7: 568 | EL7: subchronic | FA7: 31.81 | FB7: MODERATE | FC7: 82.889592 | FD7: LOW | FE7: 23.65375 | FF7: YES | FH7: 53.174082 | FI7: LOW | FJ7: 17.3 | FK7: maybe | FL7: 68.8 | FM7: 91.348201 | FN7: YES | FP7: 284 | FQ7: ECHA-exp | FS7: exp | FU7: 2 | FV7: 10 | FW7: 10 | FX7: 1 | FY7: 3 | FZ7: =FU7*FV7*FW7*FX7*FY7 -> 600 | GA7: Low (Class I) | GB7: Low (Class I) | GC7: 30 | GD7: ToxTree, Nestlé Lazar, QSAR ToolBox v 4.4 | GF7: 0.0057666667 | GI7: 6.311 | GJ7: 11.833 | GK7: 18.933 | GL7: 47.333 | GM7: ∆log<1 | GN7: 0.2 | GO7: 0.375 | GP7: 0.6 | GQ7: 1.5 | GT7: Reproductive toxicant, developmental NON-toxicant | GU7: NON-Toxicant | GV7: LOW | GW7: Reproductive toxicant, developmental NON-toxicant | GY7: Known precedent reproductive and developmental toxic potential;Miscellaneous non-cyclic chemicals (20) | HE7: Not predicted | HF7: LOW | HG7: Inactive | HH7: MODERATE | HI7: NON-active | HJ7: GOOD | HK7: Non binder, non cyclic structure | HL7: Inactive | HM7: Inactive | HO7: Inactive | HP7: EXPERIMENTAL | HQ7: Inactive | HR7: EXPERIMENTAL | HU7: Inactive | HV7: GOOD | HW7: Not predicted | HX7: LOW | IA7: Inactive | IB7: [Model ]Unable to perform Applicability Domain check. | IC7: 6.311 | ID7: 11.833 | IE7: 18.933 | IF7: 47.333 | IH7: yes
A8: 107-83-5 | B8: N-00003 | C8: CCCC(C)C | F8: CCCC(C)C | I8: 2-Methylpentane | AJ8: NON-Mutagenic | AK8: 0 | AL8: 0.825 | AM8: NON-Mutagenic | AN8: GOOD | AO8: NON-Mutagenic | AP8: GOOD | AQ8: NON-Mutagenic | AR8: MODERATE | AS8: NON-Mutagenic | AT8: GOOD | AU8: Inconclusive | AW8: Not In Domain | AX8: [No Alerts] | AY8: Not In Domain | AZ8: 0.15 | BB8: Not In Domain | BC8: 0.0747 | BD8: Not In Domain | BE8: 0.186 | BF8: Negative | BG8: Reliable (consensus score > = 0.5) | BH8: Predicted | BI8: VEGA | BU8: Inactive | BV8: GOOD | BW8: NON-genotoxic | BX8: MODERATE-Both predictions in agreement | BY8: Not In Domain | BZ8: 0.373 | CA8: No alerts for the micronucleus assay (Class II) | CF8: Not In Domain | CG8: 0.264 | CH8: Not In Domain | CI8: 0.322 | CW8: Not In Domain | CX8: Not In Domain | CY8: Inactive | CZ8: Not In Domain | DA8: Not In Domain | DB8: Not In Domain | DL8: Not In Domain | DM8: Not In Domain | DN8: Not In Domain | DO8: Not In Domain | DP8: Not In Domain | DS8: 217.628 | DU8: 210.446 | DW8: 88.1 | DX8: maybe | DY8: 257 | DZ8: maybe | FA8: 28.95 | FB8: MODERATE | FC8: 102.94375 | FD8: LOW | FE8: 16.958991 | FF8: YES | FH8: 60.380958 | FI8: LOW | FJ8: 67.5 | FK8: maybe | FL8: 49.1 | FM8: 55.030062 | FN8: YES | FP8: 2.7515031 | FQ8: CORAL LOAEL | FS8: PRED | FU8: 2 | FV8: 10 | FW8: 10 | FX8: 10 | FY8: 3 | FZ8: =FU8*FV8*FW8*FX8*FY8 -> 6000 | GA8: Low (Class I) | GB8: Low (Class I) | GC8: 30 | GD8: ToxTree, Nestlé Lazar, QSAR ToolBox v 4.4 | GF8: 0.016366667 | GN8: 0.2 | GO8: 0.375 | GP8: 0.6 | GQ8: 1.5 | GU8: NON-Toxicant | GV8: LOW | GW8: NON-Toxicant | GX8: LOW | GY8: Not known precedent reproductive and developmental toxic potential | HE8: Not predicted | HF8: LOW | HG8: Inactive | HH8: MODERATE | HI8: NON-active | HJ8: MODERATE | HK8: Non binder, non cyclic structure | HL8: Inactive | HM8: Inactive | HO8: Inactive | HP8: EXPERIMENTAL | HQ8: Inactive | HR8: EXPERIMENTAL | HU8: Inactive | HV8: GOOD | HW8: Not predicted | HX8: LOW | IA8: Inactive | IB8: [Model ]Unable to perform Applicability Domain check. | IH8: no | IK8: This substance is authorised to be used as it is covered by the SML for FCM substance 3 and 13 as mixture of alcohols.
A9: 19549-87-2 | B9: N-00004 | C9: CCC[C@H](CC(C)=C)C | F9: C=C(C)CC(C)CCC | I9: 2,4-dimethyl-1-heptene | AJ9: NON-Mutagenic | AK9: 0 | AL9: 0.9 | AM9: NON-Mutagenic | AN9: GOOD | AO9: NON-Mutagenic | AP9: GOOD | AQ9: NON-Mutagenic | AR9: GOOD | AS9: NON-Mutagenic | AT9: GOOD | AU9: Negative | AW9: Negative | AX9: [No Alerts] | AY9: Negative | AZ9: 0.155 | BB9: Negative | BC9: 0.0927 | BD9: Not In Domain | BE9: 0.104 | BF9: Negative | BG9: Reliable (consensus score > = 0.5) | BH9: Predicted | BI9: VEGA | BU9: Inactive | BV9: GOOD | BW9: NON-genotoxic | BX9: GOOD-Both predictions in agreement | BY9: Negative | BZ9: 0.359 | CA9: No alerts for the micronucleus assay (Class II) | CF9: Negative | CG9: 0.0839 | CH9: Negative | CI9: 0.0797 | CW9: Negative | CX9: Negative | CY9: Inactive | CZ9: Negative | DA9: Negative | DB9: Negative | DL9: Positive | DM9: Negative | DN9: Positive | DO9: Negative | DP9: Not In Domain | DS9: 284.805 | DU9: 318.527 | DX9: no | DY9: 7200 | DZ9: maybe | FA9: 23.34 | FB9: MODERATE | FC9: 116.78848 | FD9: MODERATE | FE9: 24.468086 | FF9: YES | FH9: 100.71636 | FI9: MODERATE | FK9: no | FL9: 62.1 | FM9: 62.187056 | FN9: YES | FP9: 3.1093528 | FQ9: CORAL LOAEL | FS9: PRED | FU9: 2 | FV9: 10 | FW9: 10 | FX9: 10 | FY9: 3 | FZ9: =FU9*FV9*FW9*FX9*FY9 -> 6000 | GA9: Low (Class I) | GB9: Low (Class I) | GC9: 30 | GD9: ToxTree, Nestlé Lazar, QSAR ToolBox v 4.4 | GF9: 0.0207 | GN9: 0.2 | GO9: 0.375 | GP9: 0.6 | GQ9: 1.5 | GU9: NON-Toxicant | GV9: LOW | GW9: NON-Toxicant | GX9: LOW | GY9: Not known precedent reproductive and developmental toxic potential | HE9: Not predicted | HF9: LOW | HG9: Inactive | HH9: MODERATE | HI9: NON-active | HJ9: GOOD | HK9: Non binder, non cyclic structure | HO9: Inactive | HP9: GOOD | HQ9: Inactive | HR9: GOOD | HU9: Inactive | HV9: GOOD | HW9: Not predicted | HX9: LOW | IA9: Inactive | IB9: [Model ]Unable to perform Applicability Domain check. | IH9: no | IK9: This molecule is also known as analytical artefact formed in the GC injector from Erucamide.
A10: 67-64-1 | B10: N-00005 | C10: CC(C)=O | F10: O=C(C)C | I10: Acetone | M10: Negative | O10: NON-Mutagenic | Q10: NON-Mutagenic | U10: NON-Mutagenic | W10: Negative | X10: Negative | Z10: Negative | AD10: Negative, Ambiguous, | AF10: Negative, | AJ10: NON-Mutagenic | AK10: 0 | AL10: 1 | AM10: NON-Mutagenic | AN10: EXPERIMENTAL | AO10: Possible NON-Mutagenic | AQ10: NON-Mutagenic | AR10: MODERATE | AS10: NON-Mutagenic | AU10: Negative | AW10: Negative | AX10: [No Alerts] | AY10: Negative | AZ10: 0.281 | BB10: Negative | BC10: 0.173 | BD10: Negative | BE10: 0.238 | BF10: Negative | BH10: Experimental | BI10: VEGA, Leadscope, ICE | BO10: Negative | BQ10: Negative, | BR10: Negative, | BS10: NON-genotoxic | BU10: Not predicted | BV10: LOW | BW10: NON-genotoxic | BX10: EXPERIMENTAL-Both predictions in agreement | BY10: Negative | BZ10: 0.443 | CA10: No alerts for the micronucleus assay (Class II) | CD10: Negative | CF10: Not In Domain | CG10: 0.594 | CH10: Negative | CI10: 0.665 | CK10: Negative | CW10: Negative | CX10: Positive | CY10: Inactive | CZ10: Positive | DA10: Not In Domain | DB10: Negative | DC10: Negative | DD10: Negative | DL10: Negative | DM10: Negative | DN10: Not In Domain | DO10: Negative | DP10: Negative | DS10: 141.349 | DU10: 313.057 | DW10: 0.043 | DX10: maybe | DZ10: no | ED10: 900 | EF10: subchronic | EG10: 900 | EH10: subchronic | EI10: 100 | EJ10: subchronic | EK10: 900 | EL10: subchronic | FA10: 59.64 | FB10: MODERATE | FC10: 80.984145 | FD10: LOW | FE10: 54.337543 | FF10: YES | FH10: 42.540246 | FI10: MODERATE | FK10: no | FL10: 81.6 | FM10: 101.99996 | FN10: YES | FP10: 50 | FQ10: Munro Toolbox-exp | FS10: exp | FU10: 2 | FV10: 10 | FW10: 10 | FX10: 1 | FY10: 3 | FZ10: =FU10*FV10*FW10*FX10*FY10 -> 600 | GA10: Low (Class I) | GB10: Low (Class I) | GC10: 30 | GD10: ToxTree, Nestlé Lazar, QSAR ToolBox v 4.4 | GE10: 0.9 | GF10: 0.0272 | IH10: no | IK10: Nitriles may be analytical artefacts from amide slip agents formed in the GC injector.
A11: 1126-79-0 | B11: N-00006 | C11: CCCCOC1=CC=CC=C1 | F11: O(c1ccccc1)CCCC | I11: Benzene, butoxy- | W11: No Call Data Present | AD11: Negative, | AJ11: NON-Mutagenic | AK11: 0 | AL11: 0.4 | AM11: NON-Mutagenic | AN11: LOW | AO11: Possible NON-Mutagenic | AP11: LOW | AQ11: NON-Mutagenic | AR11: MODERATE | AS11: NON-Mutagenic | AT11: MODERATE | AU11: Negative | AW11: Negative | AX11: [No Alerts] | AY11: Negative | AZ11: 0.0739 | BB11: Negative | BC11: 0.0452 | BD11: Negative | BE11: 0.0484 | BF11: Negative | BH11: Experimental | BI11: ECHA REACH, | BU11: Not predicted | BV11: LOW | BW11: NON-genotoxic | BX11: GOOD-Both predictions in agreement | BY11: Negative | BZ11: 0.385 | CA11: No alerts for the micronucleus assay (Class II) | CF11: Negative | CG11: 0.403 | CH11: Negative | CI11: 0.143 | CW11: Positive | CX11: Negative | CY11: Inactive | CZ11: Negative | DA11: Negative | DB11: Not In Domain | DL11: Positive | DM11: Negative | DN11: Positive | DO11: Negative | DP11: Negative | DS11: 86.912 | DU11: 268.477 | DW11: 19.5 | DX11: maybe | DY11: 46.4 | DZ11: maybe | EY11: 30 | EZ11: subchronic | FA11: 13.67 | FB11: GOOD | FC11: 87.841552 | FD11: MODERATE | FE11: 108.81781 | FF11: YES | FH11: 137.94311 | FI11: MODERATE | FJ11: 53.3 | FK11: maybe | FL11: 56.3 | FM11: 496.02093 | FN11: YES | FP11: 1.5 | FQ11: ECHA-exp | FS11: exp | FU11: 2 | FV11: 10 | FW11: 10 | FX11: 10 | FY11: 3 | FZ11: =FU11*FV11*FW11*FX11*FY11 -> 6000 | GA11: Intermediate (Class II) | GB11: Intermediate (Class II) | GC11: 9 | GD11: Nestlé Lazar, QSAR ToolBox v 4.4, | GF11: 0.005 | GN11: 0.06 | GO11: 0.1125 | GP11: 0.18 | GQ11: 0.45 | GU11: NON-Toxicant | GV11: LOW | GW11: NON-Toxicant | GX11: MODERATE | GY11: Not known precedent reproductive and developmental toxic potential | HE11: Not predicted | HF11: LOW | HG11: Inactive | HH11: LOW | HI11: NON-active | HJ11: GOOD | HK11: Non binder, without OH or NH2 group | HO11: Inactive | HP11: GOOD | HQ11: Inactive | HR11: GOOD | HU11: Inactive | HV11: GOOD | HW11: Not predicted | HX11: LOW | IA11: Inactive | IB11: [Model ]Unable to perform Applicability Domain check. | IH11: no | IK11: This substance is authorised to be used as it is covered by the SML for FCM substance 9 or 10 as mixture of acids.
A12: 108-95-2 | B12: N-00007 | C12: OC1=CC=CC=C1 | F12: Oc1ccccc1 | I12: Phenol | M12: Negative | N12: doi:10.2903/j.efsa.2013.3189 | S12: NON-Mutagenic | U12: NON-Mutagenic | W12: Negative | X12: Negative | Z12: Negative | AB12: Negative | AD12: Negative, Ambiguous, | AF12: Negative, | AH12: [-] | AJ12: NON-Mutagenic | AK12: 0 | AL12: 1 | AM12: NON-Mutagenic | AN12: MODERATE | AO12: Possible NON-Mutagenic | AP12: GOOD | AQ12: NON-Mutagenic | AS12: NON-Mutagenic | AU12: Negative | AW12: Negative | AX12: [No Alerts] | AY12: Negative | AZ12: 0.0923 | BB12: Negative | BC12: 0.103 | BD12: Negative | BE12: 0.205 | BF12: Negative-ambiguous | BH12: Experimental | BI12: ECHA REACH | BK12: positive | BL12: [+] | BM12: Active | BO12: Positive | BP12: [+] (hypothermia) | BQ12: Positive, | BR12: Positive, | BS12: Genotoxic | BU12: Not predicted | BV12: EXPERIMENTAL | BW12: Genotoxic | BX12: EXPERIMENTAL-Both predictions in agreement | BY12: Positive | BZ12: 0.613 | CA12: No alerts for the micronucleus assay (Class II) | CF12: Not In Domain | CG12: 0.566 | CH12: Positive | CI12: 0.544 | CK12: Positive | CL12: Negative | CM12: Active | CP12: Positive | CQ12: Positive | CR12: Positive | CS12: [-] | CW12: Positive | CX12: Negative | CY12: Active | CZ12: Positive | DA12: Positive | DB12: Positive | DC12: Positive | DD12: Positive | DE12: Positive | DJ12: [+] | DL12: Positive | DM12: Positive | DN12: Positive | DO12: Negative | DP12: Negative | DQ12: I | DR12: I | DS12: 188.329 | DU12: 449.573 | DW12: 134 | DX12: maybe | DY12: 233 | DZ12: maybe | ED12: 52 (BMDL10) | EF12: devtox | EG12: 52 | EH12: devtox | EI12: 153 | EJ12: chronic | EN12: 344.19323 | FA12: 21.02 | FB12: GOOD | FC12: 52.710848 | FD12: MODERATE | FE12: 59.347168 | FF12: YES | FH12: 120.53134 | FI12: MODERATE | FJ12: 112 | FK12: maybe | FL12: 71.9 | FM12: 152.58084 | FN12: YES | FP12: 34.419323 | FQ12: Lazar-exp | FS12: exp | FU12: 1 | FV12: 10 | FW12: 10 | FX12: 10 | FY12: 1 | FZ12: =FU12*FV12*FW12*FX12*FY12 -> 1000 | GA12: Low (Class I) | GB12: High (Class III) | GC12: 1.5 | GD12: Nestlé Lazar, QSAR ToolBox v 4.4, | GE12: 0.5 mg/kg-day (TDI)-applicable only to Phenol | GF12: 0.060265672 | GG12: 3E-1 mg/kg-day (US EPA RfD only for Phenol) | IH12: no | IK12: This molecule is present in paraffinic waxes and is therefore covered by its SML.
A13: 80-56-8 | B13: N-00008 | C13: CC1=CC[C@H]2C[C@@H]1C2(C)C | F13: C1=C(C)C2CC(C1)C2(C)(C) | I13: alpha-Pinene | M13: Negative | O13: NON-Mutagenic | Q13: NON-Mutagenic | U13: NON-Mutagenic | W13: Negative (3) | X13: Negative (3) | AF13: Negative, | AJ13: NON-Mutagenic | AK13: 0 | AL13: 1 | AM13: NON-Mutagenic | AN13: EXPERIMENTAL | AO13: NON-Mutagenic | AQ13: NON-Mutagenic | AR13: GOOD | AS13: NON-Mutagenic | AU13: Negative | AW13: Negative (3) | AX13: [No Alerts] | AY13: Negative (3) | AZ13: 0.108 | BB13: Negative | BC13: 0.0507 | BD13: Negative | BE13: 0.109 | BF13: Negative | BH13: Experimental | BI13: VEGA, ICE | BO13: Negative | BQ13: Negative, | BS13: NON-genotoxic | BU13: Inactive | BV13: GOOD | BW13: NON-genotoxic | BX13: EXPERIMENTAL-Both predictions in agreement | BY13: Negative | BZ13: 0.418 | CA13: No alerts for the micronucleus assay (Class II) | CF13: Negative | CG13: 0.233 | CH13: Negative | CI13: 0.404 | CW13: Negative | CX13: Negative | CY13: Inactive | CZ13: Not In Domain | DA13: Not In Domain | DB13: Not In Domain | DL13: Positive | DM13: Negative | DN13: Not In Domain | DO13: Negative | DP13: Not In Domain | DS13: 404.195 | DU13: 286.684 | DX13: no | DZ13: no | FA13: 17.75 | FB13: MODERATE | FC13: 85.585462 | FD13: MODERATE | FE13: 33.596961 | FF13: NO, reject prediction | FH13: 21.892734 | FI13: MODERATE | FK13: no | FL13: 31.5 | FM13: 201.27971 | FN13: NO, reject prediction | FP13: 3.15 | FQ13: Mazzatorta | FS13: PRED | FU13: 1 | FV13: 10 | FW13: 10 | FX13: 10 | FY13: 3 | FZ13: =FU13*FV13*FW13*FX13*FY13 -> 3000 | GA13: Low (Class I) | GB13: Low (Class I) | GC13: 30 | GD13: ToxTree, Nestlé Lazar, QSAR ToolBox v 4.4 | GF13: 0.0105 | IH13: no | IK13: Molecule is difficult to identify by GC-MS as it could be another saturated hydrocarbon as well. Note that this molecule may be part of POSH and should be assessed by its restriction.
A14: 108-88-3 | B14: N-00009 | C14: CC1=CC=CC=C1 | F14: c1ccc(cc1)C | I14: Toluene | O14: NON-Mutagenic | Q14: NON-Mutagenic | S14: NON-Mutagenic | U14: NON-Mutagenic | W14: Negative | X14: Negative | Z14: Negative | AD14: Negative, | AF14: Negative, | AH14: [-] | AJ14: NON-Mutagenic | AK14: 0 | AL14: 1 | AM14: NON-Mutagenic | AN14: EXPERIMENTAL | AO14: Possible NON-Mutagenic | AQ14: NON-Mutagenic | AS14: NON-Mutagenic | AU14: Negative | AW14: Negative | AX14: [No Alerts] | AY14: Negative | AZ14: 0.238 | BB14: Negative | BC14: 0.178 | BD14: Negative | BE14: 0.205 | BF14: Negative | BH14: Experimental | BI14: VEGA, Leadscope, ECHA REACH, ICE | BL14: [-] | BM14: Inactive | BO14: Negative | BP14: equivocal | BQ14: Negative, | BU14: Not predicted | BV14: EXPERIMENTAL | BW14: Genotoxic | BX14: MODERATE-Both predictions in agreement | BY14: Negative | BZ14: 0.512 | CA14: No alerts for the micronucleus assay (Class II) | CF14: Positive | CG14: 0.511 | CH14: Negative | CI14: 0.384 | CK14: Negative | CL14: Negative | CM14: Inactive | CN14: [-] | CS14: [E] | CW14: Negative | CX14: Negative | CY14: Inactive | CZ14: Negative | DA14: Negative | DB14: Negative | DC14: Negative | DD14: Negative | DE14: Negative | DJ14: [-] | DL14: Negative | DM14: Negative | DN14: Negative | DO14: Not In Domain | DP14: Not In Domain | DQ14: 3060m | DR14: I | DS14: 131.608 | DU14: 149.186 | DW14: 2720 | DX14: yes | DY14: 60.9 | DZ14: maybe | EI14: 590 | EJ14: subchronic | EK14: 625 | EL14: subchronic | FA14: 6.97 | FB14: GOOD | FC14: 40.513522 | FD14: MODERATE | FE14: 47.380539 | FF14: YES | FH14: 79.487713 | FI14: MODERATE | FJ14: 8.17 | FK14: maybe | FL14: 54 | FM14: 182.38957 | FN14: YES | FP14: 295 | FQ14: Munro Toolbox-exp | FS14: exp | FU14: 2 | FV14: 10 | FW14: 10 | FX14: 1 | FY14: 3 | FZ14: =FU14*FV14*FW14*FX14*FY14 -> 600 | GA14: Low (Class I) | GB14: High (Class III) | GC14: 1.5 | GD14: Nestlé Lazar, QSAR ToolBox v 4.4, | GF14: 0.0027233333 | IH14: no
A15: 100-51-6 | B15: N-00010 | C15: OCC1=CC=CC=C1 | F15: OCc1ccccc1 | I15: Benzyl alcohol | M15: Negative | O15: NON-Mutagenic | Q15: NON-Mutagenic | S15: NON-Mutagenic | U15: NON-Mutagenic | W15: Negative | X15: Negative | Z15: Negative | AD15: Negative, | AF15: Negative, | AH15: [-] | AJ15: NON-Mutagenic | AK15: 0 | AL15: 1 | AM15: NON-Mutagenic | AN15: EXPERIMENTAL | AO15: Possible NON-Mutagenic | AQ15: NON-Mutagenic | AS15: NON-Mutagenic | AU15: Negative | AW15: Negative | AX15: [No Alerts] | AY15: Negative | AZ15: 0.183 | BB15: Negative | BC15: 0.227 | BD15: Negative | BE15: 0.236 | BF15: Negative | BH15: Experimental | BI15: VEGA, Leadscope, ECHA REACH, ICE | BK15: negative | BL15: [-] | BO15: Negative | BP15: [-] | BR15: Negative, | BS15: NON-genotoxic | BU15: Not predicted | BV15: LOW | BW15: NON-genotoxic | BX15: EXPERIMENTAL-Both predictions in agreement | BY15: Negative | BZ15: 0.284 | CA15: No alerts for the micronucleus assay (Class II) | CF15: Negative | CG15: 0.462 | CH15: Negative | CI15: 0.496 | CK15: Positive | CL15: Negative | CN15: [-] | CW15: Positive | CX15: Negative | CY15: Inactive | CZ15: Negative | DA15: Negative | DB15: Negative | DC15: Negative | DD15: Negative | DJ15: [+] | DL15: Negative | DM15: Negative | DN15: Positive | DO15: Negative | DP15: Negative | DQ15: I | DR15: I | DS15: 102.78 | DU15: 148.518 | DW15: 166 | DX15: maybe | DY15: 55.1 | DZ15: maybe | ED15: 400 | EF15: chronic | EK15: 400 | EL15: chronic | EW15: 200 | EX15: chronic | FA15: 22.14 | FB15: MODERATE | FC15: 84.255838 | FD15: MODERATE | FE15: 230.78097 | FF15: YES | FH15: 157.9065 | FI15: MODERATE | FJ15: 62.5 | FK15: maybe | FL15: 232 | FM15: 642.39182 | FN15: YES | FP15: 20 | FQ15: Munro ToolBox-exp | FS15: exp | FU15: 1 | FV15: 10 | FW15: 10 | FX15: 10 | FY15: 3 | FZ15: =FU15*FV15*FW15*FX15*FY15 -> 3000 | GA15: Low (Class I) | GB15: Low (Class I) | GC15: 30 | GD15: ToxTree, Nestlé Lazar, QSAR ToolBox v 4.4 | GE15: 4 | GF15: 0.020833333 | IH15: no
A16: 75-85-4 | B16: N-00011 | C16: CCC(C)(O)C | F16: OC(C)(C)CC | I16: 2-methyl-2-butanol | M16: Negative | W16: No Call Data Present | AD16: Negative, | AJ16: NON-Mutagenic | AK16: 0 | AL16: 0.9 | AM16: NON-Mutagenic | AN16: GOOD | AO16: Possible NON-Mutagenic | AP16: GOOD | AQ16: NON-Mutagenic | AR16: GOOD | AS16: NON-Mutagenic | AT16: GOOD | AU16: Negative | AW16: Negative | AX16: [No Alerts] | AY16: Negative | AZ16: 0.198 | BB16: Negative | BC16: 0.121 | BD16: Negative | BE16: 0.206 | BF16: Negative | BH16: Experimental | BI16: ECHA REACH, | BU16: Inactive | BV16: GOOD | BW16: NON-genotoxic | BX16: GOOD-Both predictions in agreement | BY16: Negative | BZ16: 0.376 | CA16: No alerts for the micronucleus assay (Class II) | CF16: Negative | CG16: 0.355 | CH16: Negative | CI16: 0.438 | CW16: Not In Domain | CX16: Negative | CY16: Inactive | CZ16: Negative | DA16: Negative | DB16: Negative | DL16: Positive | DM16: Negative | DN16: Positive | DO16: Negative | DP16: Negative | DS16: 161.086 | DU16: 141.006 | DW16: 213 | DX16: maybe | DY16: 9570 | DZ16: maybe | FA16: 61.63 | FB16: LOW | FC16: 52.17951 | FD16: MODERATE | FE16: 57.319184 | FF16: YES | FH16: 137.65754 | FI16: MODERATE | FK16: no | FL16: 41.1 | FM16: 163.07974 | FN16: YES | FP16: 4.11 | FQ16: Mazzatorta | FS16: PRED | FU16: 1 | FV16: 10 | FW16: 10 | FX16: 10 | FY16: 3 | FZ16: =FU16*FV16*FW16*FX16*FY16 -> 3000 | GA16: High (Class III) | GB16: High (Class III) | GC16: 1.5 | GD16: ToxTree, Nestlé Lazar, QSAR ToolBox v 4.4 | GF16: 0.0137 | GI16: 0.091 | GJ16: 0.171 | GK16: 0.274 | GL16: 0.685 | GM16: ∆log<1 | GN16: 0.01 | GO16: 0.01875 | GP16: 0.03 | GQ16: 0.075 | GU16: NON-Toxicant | GV16: LOW | GW16: Toxicant | GX16: GOOD | GY16: Not known precedent reproductive and developmental toxic potential | HE16: Not predicted | HF16: LOW | HG16: Inactive | HH16: GOOD | HI16: NON-active | HJ16: GOOD | HK16: Non binder, non cyclic structure | HL16: Inactive | HM16: Inactive | HO16: Inactive | HP16: EXPERIMENTAL | HQ16: Inactive | HR16: EXPERIMENTAL | HU16: Inactive | HV16: GOOD | HW16: Not predicted | HX16: LOW | IA16: Inactive | IB16: [Model ]Unable to perform Applicability Domain check. | IC16: 0.091 | ID16: 0.171 | IE16: 0.274 | IF16: 0.685 | IH16: yes
A17: 763-32-6 | B17: N-00012 | C17: CC(CCO)=C | F17: OCCC(=C)C | I17: 3-buten-1-ol, 3-methyl | M17: Negative | W17: No Call Data Present | AD17: Negative, | AJ17: NON-Mutagenic | AK17: 0 | AL17: 0.9 | AM17: NON-Mutagenic | AN17: GOOD | AO17: Possible NON-Mutagenic | AP17: GOOD | AQ17: NON-Mutagenic | AR17: GOOD | AS17: NON-Mutagenic | AT17: GOOD | AU17: Negative | AW17: Negative | AX17: [No Alerts] | AY17: Negative | AZ17: 0.236 | BB17: Negative | BC17: 0.2 | BD17: Negative | BE17: 0.209 | BF17: Negative | BH17: Experimental | BI17: ECHA REACH, | BU17: Not predicted | BV17: LOW | BW17: NON-genotoxic | BX17: GOOD-Both predictions in agreement | BY17: Negative | BZ17: 0.377 | CA17: No alerts for the micronucleus assay (Class II) | CF17: Negative | CG17: 0.478 | CH17: Negative | CI17: 0.463 | CW17: Not In Domain | CX17: Negative | CY17: Inactive | CZ17: Negative | DA17: Negative | DB17: Negative | DL17: Positive | DM17: Negative | DN17: Positive | DO17: Negative | DP17: Negative | DS17: 140.737 | DU17: 209.155 | DW17: 979 | DX17: maybe | DY17: 947 | DZ17: maybe | FA17: 66.16 | FB17: LOW | FC17: 114.86825 | FD17: MODERATE | FE17: 41.010966 | FF17: YES | FH17: 95.499259 | FI17: MODERATE | FK17: no | FL17: 237 | FM17: 80.686337 | FN17: YES | FP17: 4.0343169 | FQ17: CORAL LOAEL | FS17: PRED | FU17: 2 | FV17: 10 | FW17: 10 | FX17: 10 | FY17: 3 | FZ17: =FU17*FV17*FW17*FX17*FY17 -> 6000 | GA17: Low (Class I) | GB17: Low (Class I) | GC17: 30 | GD17: ToxTree, Nestlé Lazar, QSAR ToolBox v 4.4 | GF17: 0.06835161 | GN17: 0.2 | GO17: 0.375 | GP17: 0.6 | GQ17: 1.5 | GU17: Toxicant | GV17: GOOD | GW17: Toxicant | GX17: GOOD | GY17: Not known precedent reproductive and developmental toxic potential | HE17: Not predicted | HF17: LOW | HG17: Inactive | HH17: GOOD | HI17: NON-active | HJ17: GOOD | HK17: Non binder, non cyclic structure | HO17: Inactive | HP17: GOOD | HQ17: Inactive | HR17: GOOD | HU17: Inactive | HV17: GOOD | HW17: Not predicted | HX17: LOW | IA17: Inactive | IB17: [Model ]Unable to perform Applicability Domain check. | IH17: no
A18: 109-86-4 | B18: N-00013 | C18: COCCO | F18: OCCOC | I18: Ethanol, 2-methoxy- | O18: NON-Mutagenic | Q18: NON-Mutagenic | U18: NON-Mutagenic | W18: Negative | X18: Negative | Z18: Negative | AD18: Negative, | AF18: Negative, | AH18: [-] | AJ18: NON-Mutagenic | AK18: 0 | AL18: 1 | AM18: NON-Mutagenic | AN18: EXPERIMENTAL | AO18: Possible NON-Mutagenic | AQ18: NON-Mutagenic | AR18: MODERATE | AS18: NON-Mutagenic | AU18: Negative | AW18: Negative | AX18: [No Alerts] | AY18: Negative | AZ18: 0.231 | BB18: Negative | BC18: 0.2 | BD18: Negative | BE18: 0.306 | BF18: Negative | BH18: Experimental | BI18: VEGA, Leadscope, ECHA REACH, ICE | BU18: Not predicted | BV18: LOW | BW18: NON-genotoxic | BX18: MODERATE-Both predictions in agreement | BY18: Positive | BZ18: 0.713 | CA18: At least one positive structural alerts for the micronucleus assay (Class I) | CF18: Not In Domain | CG18: 0.599 | CH18: Positive | CI18: 0.709 | CN18: [-] | CP18: Negative | CQ18: Negative | CS18: [-] | CW18: Not In Domain | CX18: Not In Domain | CY18: Inactive | CZ18: Negative | DA18: Negative | DB18: Not In Domain | DF18: Positive | DG18: Positive | DJ18: [+] | DL18: Not In Domain | DM18: Positive | DN18: Positive | DO18: Positive | DP18: Positive | DS18: 88.289 | DU18: 174.802 | DW18: 184 | DX18: maybe | DY18: 232 | DZ18: maybe | EK18: 11 | EL18: devtox | EW18: 25 | EX18: devtox | FA18: 82.72 | FB18: MODERATE | FC18: 83.96533 | FD18: LOW | FE18: 289.26774 | FF18: YES | FH18: 178.93694 | FI18: MODERATE | FJ18: 702 | FK18: maybe | FL18: 229 | FM18: 720.94146 | FN18: YES | FP18: 2.5 | FQ18: Munro ToolBox-exp | FS18: exp | FU18: 1 | FV18: 10 | FW18: 10 | FX18: 10 | FY18: 1 | FZ18: =FU18*FV18*FW18*FX18*FY18 -> 1000 | GA18: Low (Class I) | GB18: Low (Class I) | GC18: 30 | GD18: ToxTree, Nestlé Lazar, QSAR ToolBox v 4.4 | GF18: 0.025 | GN18: 0.2 | GO18: 0.375 | GP18: 0.6 | GQ18: 1.5 | GT18: Reproductive and developmental toxicant | GU18: Toxicant | GV18: GOOD | GW18: Reproductive and developmental toxicant | GX18: EXPERIMENTAL | GY18: Alkoxy propanol derivatives;Di-substituted hydrocarbons (24a);Known precedent reproductive and developmental toxic potential | GZ18: NON-active | HB18: NON-active | HE18: NON-active | HF18: EXPERIMENTAL | HG18: Inactive | HH18: GOOD | HI18: NON-active | HJ18: EXPERIMENTAL | HK18: Non binder, non cyclic structure | HL18: Inactive | HM18: Inactive | HO18: Inactive | HP18: EXPERIMENTAL | HQ18: Inactive | HR18: EXPERIMENTAL | HU18: Inactive | HV18: GOOD | HW18: Not predicted | HX18: LOW | IA18: Inactive | IB18: [Model ]Unable to perform Applicability Domain check. | IH18: no
A19: 637-92-3 | B19: N-00014 | C19: CCOC(C)(C)C | F19: O(CC)C(C)(C)C | I19: Propane, 2-ethoxy-2-methyl- | M19: Negative | O19: NON-Mutagenic | Q19: NON-Mutagenic | U19: NON-Mutagenic | W19: Negative | X19: Negative | Z19: Negative | AD19: Negative, | AF19: Negative, | AJ19: NON-Mutagenic | AK19: 0 | AL19: 1 | AM19: NON-Mutagenic | AN19: EXPERIMENTAL | AO19: NON-Mutagenic | AQ19: NON-Mutagenic | AR19: MODERATE | AS19: NON-Mutagenic | AU19: Negative | AW19: Negative | AX19: [No Alerts] | AY19: Negative | AZ19: 0.262 | BB19: Negative | BC19: 0.0851 | BD19: Negative | BE19: 0.194 | BF19: Negative | BH19: Experimental | BI19: VEGA, Leadscope, ECHA REACH, ICE | BO19: Negative | BQ19: Negative, | BR19: Negative, | BS19: NON-genotoxic | BU19: Inactive | BV19: GOOD | BW19: NON-genotoxic | BX19: EXPERIMENTAL-Both predictions in agreement | BY19: Negative | BZ19: 0.475 | CA19: No alerts for the micronucleus assay (Class II) | CF19: Positive | CG19: 0.504 | CH19: Negative | CI19: 0.498 | CW19: Not In Domain | CX19: Positive | CY19: Inactive | CZ19: Negative | DA19: Positive | DB19: Not In Domain | DL19: Positive | DM19: Positive | DN19: Positive | DO19: Negative | DP19: Negative | DS19: 198.303 | DU19: 224.96 | DX19: no | DY19: 3100 | DZ19: maybe | ED19: 100 | EF19: chronic | EK19: 121 | EL19: chronic | FA19: 34.3 | FB19: MODERATE | FC19: 91.306144 | FD19: LOW | FE19: 29.744043 | FF19: YES | FH19: 151.73997 | FI19: MODERATE | FK19: no | FL19: 29.3 | FM19: 99.976977 | FN19: YES | FP19: 100 | FQ19: EFSA OFT db-exp | FS19: exp | FU19: 1 | FV19: 10 | FW19: 10 | FX19: 1 | FY19: 3 | FZ19: =FU19*FV19*FW19*FX19*FY19 -> 300 | GA19: High (Class III) | GB19: High (Class III) | GC19: 1.5 | GD19: QSAR ToolBox v 4.4, | GE19: 1 | GF19: 0.0097666667 | GI19: 2.222 | GJ19: 4.167 | GK19: 6.667 | GL19: 16.667 | GM19: ∆log<1 | GN19: 0.01 | GO19: 0.01875 | GP19: 0.03 | GQ19: 0.075 | GU19: Toxicant | GV19: GOOD | GW19: Toxicant | GX19: LOW | GY19: Not known precedent reproductive and developmental toxic potential | HE19: Possible NON-active | HF19: GOOD | HG19: Inactive | HH19: MODERATE | HI19: NON-active | HJ19: GOOD | HK19: Non binder, non cyclic structure | HL19: Inactive | HM19: Inactive | HO19: Inactive | HP19: EXPERIMENTAL | HQ19: Inactive | HR19: EXPERIMENTAL | HU19: Inactive | HV19: GOOD | HW19: Not predicted | HX19: LOW | IA19: Inactive | IB19: [Model ]Unable to perform Applicability Domain check. | IC19: 2.222 | ID19: 4.167 | IE19: 6.667 | IF19: 16.667 | IH19: yes
A20: 556-67-2 | B20: N-00015 | C20: C[Si]1(O[Si](C)(O[Si](C)(O[Si](C)(O1)C)C)C)C | F20: O1[Si](O[Si](O[Si](O[Si]1(C)C)(C)C)(C)C)(C)C | I20: Cyclotetrasiloxane, octamethyl | J20: 2021-063 | K20: Y | M20: Negative | W20: Negative | X20: Negative | Z20: Negative | AD20: Negative, | AJ20: NON-Mutagenic | AK20: 0 | AL20: 0.3 | AM20: NON-Mutagenic | AN20: LOW | AO20: Possible NON-Mutagenic | AP20: LOW | AQ20: NON-Mutagenic | AR20: LOW | AS20: NON-Mutagenic | AT20: MODERATE | AU20: Negative | AW20: Negative | AX20: [No Alerts] | AY20: Negative | AZ20: 0.0916 | BB20: Negative | BC20: 0.0587 | BD20: Negative | BE20: 0.0263 | BF20: Negative | BH20: Experimental | BI20: Leadscope, ECHA REACH, | BR20: Negative, | BU20: Not predicted | BV20: LOW | BW20: Not predicted | BX20: -Not available | BY20: Not In Domain | BZ20: 0.617 | CA20: No alerts for the micronucleus assay (Class II) | CC20: Negative | CD20: Negative | CF20: Negative | CG20: 0.474 | CH20: Negative | CI20: 0.55 | CW20: Not In Domain | CX20: Not In Domain | CY20: Inactive | CZ20: Not In Domain | DA20: Not In Domain | DB20: Not In Domain | DL20: Not In Domain | DM20: Not In Domain | DN20: Not In Domain | DO20: Not In Domain | DP20: Not In Domain | DS20: 6361.315 | DT20: out of AD | DU20: 3057.581 | DV20: out of AD | DX20: no | DZ20: no | EK20: 373.75 | EL20: chronic | FA20: 0.0003 | FB20: LOW | FC20: 110.12857 | FD20: LOW | FE20: 0.010185914 | FF20: YES | FH20: 179.59738 | FI20: LOW | FK20: no | FL20: 0.01 | FM20: 0.14236394 | FN20: YES | FP20: 373.75 | FQ20: ECHA-exp | FS20: exp | FU20: 1 | FV20: 10 | FW20: 10 | FX20: 1 | FY20: 3 | FZ20: =FU20*FV20*FW20*FX20*FY20 -> 300 | GA20: High (Class III) | GB20: High (Class III) | GC20: 1.5 | GD20: ToxTree, Nestlé Lazar, QSAR ToolBox v 4.4 | GF20: 3.3333333e-06 | GI20: 2.47 | GN20: Not derived | GO20: Not derived | GP20: Not derived | GQ20: Not derived | GR20: not applied | GU20: Toxicant | GV20: LOW | GW20: Toxicant | GX20: MODERATE | GY20: Not known precedent reproductive and developmental toxic potential | GZ20: NON-active | HB20: NON-active | HE20: NON-active | HF20: EXPERIMENTAL | HG20: Inactive | HH20: LOW | HI20: NON-active | HJ20: EXPERIMENTAL | HK20: Non binder, non cyclic structure | HL20: Inactive | HM20: Inactive | HO20: Inactive | HP20: EXPERIMENTAL | HQ20: Inactive | HR20: EXPERIMENTAL | HU20: Inactive | HV20: LOW | HW20: Not predicted | HX20: LOW | IA20: Inactive | IB20: [Model ]Unable to perform Applicability Domain check. | IC20: 2.47 | IH20: yes
A21: 111-77-3 | B21: N-00016 | C21: COCCOCCO | F21: OCCOCCOC | I21: Diethyleneglycol methyl ether | W21: Negative | X21: Negative | Z21: Negative | AD21: Negative, | AF21: Negative, | AJ21: NON-Mutagenic | AK21: 0 | AL21: 0.825 | AM21: NON-Mutagenic | AN21: GOOD | AO21: NON-Mutagenic | AP21: GOOD | AQ21: NON-Mutagenic | AR21: GOOD | AS21: NON-Mutagenic | AT21: MODERATE | AU21: Negative | AW21: Negative | AX21: [No Alerts] | AY21: Negative | AZ21: 0.291 | BB21: Negative | BC21: 0.369 | BD21: Negative | BE21: 0.305 | BF21: Negative | BH21: Experimental | BI21: Leadscope, ECHA REACH, ICE | BU21: Not predicted | BV21: LOW | BW21: NON-genotoxic | BX21: GOOD-Both predictions in agreement | BY21: Positive | BZ21: 0.703 | CA21: At least one positive structural alerts for the micronucleus assay (Class I) | CF21: Not In Domain | CG21: 0.567 | CH21: Positive | CI21: 0.7 | CW21: Not In Domain | CX21: Not In Domain | CY21: Inactive | CZ21: Negative | DA21: Positive | DB21: Not In Domain | DL21: Not In Domain | DM21: Positive | DN21: Positive | DO21: Not In Domain | DP21: Positive | DS21: 95.651 | DU21: 164.726 | DW21: 399 | DX21: maybe | DY21: 261 | DZ21: maybe | EK21: 900 | EL21: subchronic | FA21: 87.81 | FB21: MODERATE | FC21: 124.27964 | FD21: LOW | FE21: 542.62525 | FF21: YES | FH21: 372.04888 | FI21: MODERATE | FJ21: 1450 | FK21: maybe | FL21: 309 | FM21: 1208.6485 | FN21: YES | FP21: 450 | FQ21: ECHA-exp | FS21: exp | FU21: 2 | FV21: 10 | FW21: 10 | FX21: 1 | FY21: 3 | FZ21: =FU21*FV21*FW21*FX21*FY21 -> 600 | GA21: Low (Class I) | GB21: Low (Class I) | GC21: 30 | GD21: ToxTree, Nestlé Lazar, QSAR ToolBox v 4.4 | GF21: 0.103 | GI21: 10 | GJ21: 18.75 | GK21: 30 | GL21: 75 | GM21: ∆log<1 | GN21: 0.2 | GO21: 0.375 | GP21: 0.6 | GQ21: 1.5 | GU21: Toxicant | GV21: GOOD | GW21: Toxicant | GX21: GOOD | GY21: Di-substituted hydrocarbons (24b);Known precedent reproductive and developmental toxic potential | GZ21: NON-active | HB21: NON-active | HE21: NON-active | HF21: EXPERIMENTAL | HG21: Inactive | HH21: GOOD | HI21: NON-active | HJ21: EXPERIMENTAL | HK21: Non binder, non cyclic structure | HL21: Inactive | HM21: Inactive | HO21: Inactive | HP21: EXPERIMENTAL | HQ21: Inactive | HR21: EXPERIMENTAL | HS21: Inactive | HU21: Inactive | HV21: EXPERIMENTAL | HW21: Not predicted | HX21: LOW | IA21: Inactive | IB21: [Model ]Unable to perform Applicability Domain check. | IC21: 10 | ID21: 18.75 | IE21: 30 | IF21: 75 | IH21: yes
A22: 13466-78-9 | B22: N-00017 | C22: CC1=CC[C@H]2[C@H](C2(C)C)C1 | F22: C1=C(C)CC2C(C1)C2(C)(C) | I22: 3-Carene | M22: Negative | W22: No Call Data Present | AJ22: NON-Mutagenic | AK22: 0 | AL22: 0.9 | AM22: NON-Mutagenic | AN22: GOOD | AO22: NON-Mutagenic | AP22: GOOD | AQ22: NON-Mutagenic | AR22: GOOD | AS22: NON-Mutagenic | AT22: GOOD | AU22: Negative | AW22: Negative | AX22: [No Alerts] | AY22: Negative | AZ22: 0.131 | BB22: Negative | BC22: 0.0414 | BD22: Negative | BE22: 0.109 | BF22: Negative | BG22: Reliable (consensus score > = 0.5) | BH22: Predicted | BI22: VEGA | BU22: Inactive | BV22: GOOD | BW22: NON-genotoxic | BX22: MODERATE-Both predictions in agreement | BY22: Negative | BZ22: 0.418 | CA22: No alerts for the micronucleus assay (Class II) | CF22: Negative | CG22: 0.118 | CH22: Negative | CI22: 0.404 | CW22: Negative | CX22: Negative | CY22: Inactive | CZ22: Not In Domain | DA22: Not In Domain | DB22: Not In Domain | DL22: Positive | DM22: Negative | DN22: Not In Domain | DO22: Negative | DP22: Not In Domain | DS22: 336.65 | DU22: 232.627 | DX22: no | DZ22: no | FA22: 17.75 | FB22: MODERATE | FC22: 119.72918 | FD22: MODERATE | FE22: 33.596961 | FF22: NO, reject prediction | FH22: 85.486985 | FI22: MODERATE | FK22: no | FL22: 31.5 | FM22: 201.27971 | FN22: NO, reject prediction | FP22: 3.15 | FQ22: Mazzatorta | FS22: PRED | FU22: 1 | FV22: 10 | FW22: 10 | FX22: 10 | FY22: 3 | FZ22: =FU22*FV22*FW22*FX22*FY22 -> 3000 | GA22: Low (Class I) | GB22: Low (Class I) | GC22: 30 | GD22: ToxTree, Nestlé Lazar, QSAR ToolBox v 4.4 | GF22: 0.0105 | GN22: 0.2 | GO22: 0.375 | GP22: 0.6 | GQ22: 1.5 | GU22: NON-Toxicant | GV22: LOW | GW22: NON-Toxicant | GX22: LOW | GY22: Not known precedent reproductive and developmental toxic potential | HE22: Not predicted | HF22: LOW | HG22: Inactive | HH22: GOOD | HI22: NON-active | HJ22: GOOD | HK22: Non binder, without OH or NH2 group | HL22: Inactive | HM22: Inactive | HO22: Inactive | HP22: EXPERIMENTAL | HQ22: Inactive | HR22: EXPERIMENTAL | HU22: Inactive | HV22: GOOD | HW22: Not predicted | HX22: LOW | IA22: Inactive | IB22: [Model ]Unable to perform Applicability Domain check. | IH22: no
A23: 22347-47-3 | B23: N-00018 | C23: O[C@H]1OCCOC1 | F23: OC1OCCOC1 | I23: 1,4-Dioxan-2-ol | AJ23: NON-Mutagenic | AK23: 0.05 | AL23: 0.6 | AM23: Mutagenic | AN23: LOW | AO23: NON-Mutagenic | AP23: GOOD | AQ23: NON-Mutagenic | AR23: GOOD | AS23: NON-Mutagenic | AT23: MODERATE | AU23: Negative | AW23: Negative | AX23: [No Alerts] | AY23: Negative | AZ23: 0.312 | BA23: muta probability >0.2 | BB23: Negative | BC23: 0.181 | BD23: Negative | BE23: 0.333 | BF23: Negative | BG23: moderate (consensus score > = 0.5 & 1 single positive low rel prediction ) | BH23: Predicted | BI23: VEGA | BU23: Not predicted | BV23: LOW | BW23: NON-genotoxic | BX23: GOOD-Both predictions in agreement | BY23: Positive | BZ23: 0.721 | CA23: At least one positive structural alerts for the micronucleus assay (Class I) | CF23: Not In Domain | CG23: 0.6 | CH23: Not In Domain | CI23: 0.714 | CW23: Negative | CX23: Not In Domain | CY23: Inactive | CZ23: Positive | DA23: Positive | DB23: Negative | DL23: Not In Domain | DM23: Positive | DN23: Not In Domain | DO23: Not In Domain | DP23: Negative | DS23: 162.222 | DU23: 182.509 | DW23: 131 | DX23: maybe | DY23: 191 | DZ23: maybe | FA23: 84.32 | FB23: LOW | FC23: 97.140425 | FD23: LOW | FE23: 510.03502 | FF23: YES | FH23: 66.78824 | FI23: LOW | FK23: no | FL23: 54.5 | FM23: 1057.3043 | FN23: YES | FP23: 5.45 | FQ23: Mazzatorta | FS23: PRED | FU23: 1 | FV23: 10 | FW23: 10 | FX23: 10 | FY23: 3 | FZ23: =FU23*FV23*FW23*FX23*FY23 -> 3000 | GA23: High (Class III) | GB23: High (Class III) | GC23: 1.5 | GD23: ToxTree, Nestlé Lazar, QSAR ToolBox v 4.4 | GF23: 0.018166667 | GI23: 0.121 | GJ23: 0.227 | GK23: 0.363 | GL23: 0.908 | GM23: ∆log<1 | GN23: 0.01 | GO23: 0.01875 | GP23: 0.03 | GQ23: 0.075 | GU23: Toxicant | GV23: GOOD | GW23: Toxicant | GX23: GOOD | GY23: Known precedent reproductive and developmental toxic potential;Piperazine-, dioxane-, morpholine-, tetrahydrothiopyran-like derivatives and cyclohexanamine (17c) | HE23: Possible NON-active | HF23: GOOD | HG23: Inactive | HH23: MODERATE | HI23: NON-active | HJ23: GOOD | HK23: Non binder, impaired OH or NH2 group | HO23: Inactive | HP23: GOOD | HQ23: Inactive | HR23: GOOD | HU23: Inactive | HV23: GOOD | HW23: Not predicted | HX23: LOW | IA23: Inactive | IB23: [Model ]Unable to perform Applicability Domain check. | IC23: 0.121 | ID23: 0.227 | IE23: 0.363 | IF23: 0.908 | IH23: yes
A24: 127-91-3 | B24: N-00019 | C24: CC1(C)[C@@H]2CCC([C@H]1C2)=C | F24: C=C1CCC2CC1C2(C)(C) | I24: beta-Pinene | M24: Negative | O24: NON-Mutagenic | Q24: NON-Mutagenic | U24: NON-Mutagenic | W24: Negative | X24: Negative | AJ24: NON-Mutagenic | AK24: 0 | AL24: 1 | AM24: NON-Mutagenic | AN24: EXPERIMENTAL | AO24: NON-Mutagenic | AQ24: NON-Mutagenic | AR24: GOOD | AS24: NON-Mutagenic | AU24: Negative | AW24: Negative | AX24: [No Alerts] | AY24: Negative | AZ24: 0.241 | BB24: Negative | BC24: 0.133 | BD24: Not In Domain | BE24: 0.104 | BF24: Negative | BH24: Experimental | BI24: VEGA, Leadscope, | BU24: Inactive | BV24: GOOD | BW24: NON-genotoxic | BX24: MODERATE-Both predictions in agreement | BY24: Negative | BZ24: 0.442 | CA24: No alerts for the micronucleus assay (Class II) | CF24: Not In Domain | CG24: 0.367 | CH24: Not In Domain | CI24: 0.394 | CW24: Negative | CX24: Not In Domain | CY24: Inactive | CZ24: Negative | DA24: Negative | DB24: Negative | DL24: Positive | DM24: Negative | DN24: Not In Domain | DO24: Negative | DP24: Not In Domain | DS24: 439.763 | DU24: 291.991 | DX24: no | DZ24: no | FA24: 17.75 | FB24: MODERATE | FC24: 72.22707 | FD24: MODERATE | FE24: 17.068682 | FF24: YES | FH24: 15.62428 | FI24: MODERATE | FK24: no | FL24: 31.5 | FM24: 104.47202 | FN24: YES | FP24: 3.15 | FQ24: Mazzatorta | FS24: PRED | FU24: 1 | FV24: 10 | FW24: 10 | FX24: 10 | FY24: 3 | FZ24: =FU24*FV24*FW24*FX24*FY24 -> 3000 | GA24: Low (Class I) | GB24: Low (Class I) | GC24: 30 | GD24: ToxTree, Nestlé Lazar, QSAR ToolBox v 4.4 | GF24: 0.0105 | IH24: no
A25: 558-42-9 | B25: N-00020 | C25: CC(CCl)(O)C | F25: OC(C)(C)CCl | I25: 1-Chloro-2-methyl-2-propanol | AJ25: Mutagenic | AK25: 0.9 | AL25: 0 | AM25: Suspect Mutagenic | AN25: GOOD | AO25: Mutagenic | AP25: GOOD | AQ25: Mutagenic | AR25: GOOD | AS25: Mutagenic | AT25: GOOD | AU25: Positive | AW25: Negative | AX25: [No Alerts] | AY25: Positive | AZ25: 0.768 | BB25: Positive | BC25: 0.744 | BD25: Indeterminate | BE25: 0.48 | BF25: Positive | BG25: Reliable (consensus score > = 0.5) | BH25: Predicted | BI25: Leadscope | BU25: Inactive | BV25: LOW | BW25: NON-genotoxic | BX25: GOOD-Both predictions in agreement | BY25: Negative | BZ25: 0.451 | CA25: At least one positive structural alerts for the micronucleus assay (Class I) | CF25: Positive | CG25: 0.674 | CH25: Positive | CI25: 0.546 | CW25: Positive | CX25: Negative | CY25: Inactive | CZ25: Negative | DA25: Not In Domain | DB25: Negative | DL25: Positive | DM25: Positive | DN25: Positive | DO25: Negative | DP25: Negative | DS25: 206.929 | DU25: 136.226 | DX25: no | DZ25: no | FA25: 95.42 | FB25: LOW | FC25: 44.915889 | FD25: LOW | FE25: 8.6456968 | FF25: YES | FH25: 121.70264 | FI25: LOW | FK25: no | FL25: 33.4 | FM25: 16.251745 | FN25: YES | GC25: 0.0025 | GI25: Not derived | GJ25: Not derived | GK25: Not derived | GL25: Not derived | GN25: Not derived | GO25: Not derived | GP25: Not derived | GQ25: Not derived | GU25: NON-Toxicant | GV25: LOW | GW25: Toxicant | GX25: MODERATE | GY25: Not known precedent reproductive and developmental toxic potential | HE25: NON-active | HF25: GOOD | HG25: Inactive | HH25: GOOD | HI25: NON-active | HJ25: GOOD | HK25: Non binder, non cyclic structure | HO25: Inactive | HP25: GOOD | HQ25: Inactive | HR25: GOOD | HU25: Inactive | HV25: GOOD | HW25: Not predicted | HX25: LOW | IA25: Inactive | IB25: [Model ]Unable to perform Applicability Domain check. | IC25: Not derived | ID25: Not derived | IE25: Not derived | IF25: Not derived | IH25: no
A26: 104-76-7 | B26: N-00021 | C26: CCCCC(CO)CC | F26: OCC(CC)CCCC | I26: 2-Ethyl-1-hexanol | M26: Negative | O26: NON-Mutagenic | Q26: NON-Mutagenic | W26: Negative | X26: Negative | AB26: Negative | AD26: Negative, | AF26: Negative, | AJ26: NON-Mutagenic | AK26: 0 | AL26: 1 | AM26: NON-Mutagenic | AN26: EXPERIMENTAL | AO26: NON-Mutagenic | AQ26: NON-Mutagenic | AR26: MODERATE | AS26: NON-Mutagenic | AT26: GOOD | AU26: Negative | AW26: Negative | AX26: [No Alerts] | AY26: Negative | AZ26: 0.17 | BB26: Negative | BC26: 0.104 | BD26: Negative | BE26: 0.0817 | BF26: Negative | BH26: Experimental | BI26: VEGA, Leadscope, ECHA REACH, ICE | BO26: Negative | BR26: Negative, | BU26: Inactive | BV26: GOOD | BW26: NON-genotoxic | BX26: MODERATE-Both predictions in agreement | BY26: Negative | BZ26: 0.358 | CA26: No alerts for the micronucleus assay (Class II) | CF26: Negative | CG26: 0.0547 | CH26: Negative | CI26: 0.0476 | CK26: Negative | CW26: Negative | CX26: Negative | CY26: Inactive | CZ26: Negative | DA26: Negative | DB26: Negative | DL26: Positive | DM26: Negative | DN26: Positive | DO26: Negative | DP26: Negative | DQ26: I | DR26: 1680 | DS26: 266.379 | DU26: 211.838 | DW26: 6.96 | DX26: maybe | DY26: 594 | DZ26: maybe | ED26: 50 | EF26: chronic | EG26: 50 | EH26: chronic | EK26: 200 | EL26: chronic | EW26: 250 | EX26: subchronic | FA26: 102.03 | FB26: LOW | FC26: 140.83156 | FD26: MODERATE | FE26: 71.862116 | FF26: YES | FH26: 126.24088 | FI26: MODERATE | FJ26: 50.5 | FK26: maybe | FL26: 275 | FM26: 245.98011 | FN26: YES | FP26: 12.5 | FQ26: Munro ToolBox-exp | FS26: exp | FU26: 2 | FV26: 10 | FW26: 10 | FX26: 10 | FY26: 3 | FZ26: =FU26*FV26*FW26*FX26*FY26 -> 6000 | GA26: Low (Class I) | GB26: Low (Class I) | GC26: 30 | GD26: ToxTree, Nestlé Lazar, QSAR ToolBox v 4.4 | GE26: 0.5 | GF26: 0.016833333 | IH26: no
A27: 110-13-4 | B27: N-00022 | C27: CC(CCC(C)=O)=O | F27: O=C(C)CCC(=O)C | I27: 2,5-Hexanedione | O27: NON-Mutagenic | Q27: NON-Mutagenic | U27: NON-Mutagenic | W27: Negative | X27: Negative | AJ27: NON-Mutagenic | AK27: 0 | AL27: 1 | AM27: NON-Mutagenic | AN27: EXPERIMENTAL | AO27: Possible NON-Mutagenic | AQ27: NON-Mutagenic | AR27: MODERATE | AS27: NON-Mutagenic | AU27: Negative | AW27: Negative | AX27: [No Alerts] | AY27: Negative | AZ27: 0.176 | BB27: Negative | BC27: 0.098 | BD27: Negative | BE27: 0.205 | BF27: Negative | BH27: Experimental | BI27: VEGA, Leadscope, | BU27: Inactive | BV27: MODERATE | BW27: NON-genotoxic | BX27: MODERATE-Both predictions in agreement | BY27: Negative | BZ27: 0.361 | CA27: At least one positive structural alerts for the micronucleus assay (Class I) | CF27: Negative | CG27: 0.37 | CH27: Positive | CI27: 0.652 | CW27: Negative | CX27: Negative | CY27: Inactive | CZ27: Positive | DA27: Not In Domain | DB27: Negative | DL27: Positive | DM27: Negative | DN27: Not In Domain | DO27: Negative | DP27: Positive | DS27: 26.518 | DU27: 418.719 | DW27: 0.0838 | DX27: maybe | DZ27: no | FA27: 114.88 | FB27: GOOD | FC27: 125.1123 | FD27: MODERATE | FE27: 88.674756 | FF27: YES | FH27: 161.13875 | FI27: MODERATE | FK27: no | FL27: 178 | FM27: 196.74332 | FN27: YES | FP27: 9.8371661 | FQ27: CORAL LOAEL | FS27: PRED | FU27: 2 | FV27: 10 | FW27: 10 | FX27: 10 | FY27: 3 | FZ27: =FU27*FV27*FW27*FX27*FY27 -> 6000 | GA27: High (Class III) | GB27: High (Class III) | GC27: 1.5 | GD27: ToxTree, Nestlé Lazar, QSAR ToolBox v 4.4 | GF27: 0.059333333 | GI27: 0.219 | GJ27: 0.41 | GK27: 0.656 | GL27: 1.64 | GM27: ∆log<1 | GN27: 0.01 | GO27: 0.01875 | GP27: 0.03 | GQ27: 0.075 | GT27: Reproductive toxicant (no data on developmental toxicity) | GU27: NON-Toxicant | GV27: LOW | GW27: Reproductive toxicant no data on developmental toxicity) | GY27: Known precedent reproductive and developmental toxic potential;Miscellaneous non-cyclic chemicals (20) | HE27: Possible NON-active | HF27: GOOD | HG27: Inactive | HH27: GOOD | HI27: NON-active | HJ27: GOOD | HK27: Non binder, non cyclic structure | HL27: Inactive | HM27: Inactive | HO27: Inactive | HP27: EXPERIMENTAL | HQ27: Inactive | HR27: EXPERIMENTAL | HU27: Inactive | HV27: GOOD | HW27: Not predicted | HX27: LOW | IA27: Inactive | IB27: [Model ]Unable to perform Applicability Domain check. | IC27: 0.219 | ID27: 0.41 | IE27: 0.656 | IF27: 1.64 | IH27: yes
A28: 629-96-9 | B28: N-00023 | C28: [H]O[C@]([H])([H])[C@]([H])([H])[C@]([H])([H])[C@]([H])([H])[C@]([H])([H])[C@]([H])([H])[C@]([H])([H])[C@]([H])([H])[C@]([H])([H])[C@]([H])([H])[C@@]([H])([H])[C@@]([H])([H])[C@@]([H])([H])[C@@]([H])([H])[C@@]([H])([H])[C@@]([H])([H])[C@@]([H])([H])[C@@]([H])([H])[C@@]([H])([H])[C@@]([H])([H])[H] | F28: OCCCCCCCCCCCCCCCCCCCC | I28: 1-Eicosanol | W28: No Call Data Present | AJ28: NON-Mutagenic | AK28: 0 | AL28: 0.675 | AM28: NON-Mutagenic | AN28: MODERATE | AO28: NON-Mutagenic | AP28: MODERATE | AQ28: NON-Mutagenic | AR28: MODERATE | AS28: NON-Mutagenic | AT28: GOOD | AU28: Negative | AW28: Negative | AX28: [No Alerts] | AY28: Negative | AZ28: 0.0545 | BB28: Negative | BC28: 0.0341 | BD28: Negative | BE28: 0.0421 | BF28: Negative | BG28: Reliable (consensus score > = 0.5) | BH28: Predicted | BI28: VEGA | BU28: Inactive | BV28: GOOD | BW28: NON-genotoxic | BX28: MODERATE-Both predictions in agreement | BY28: Negative | BZ28: 0.224 | CA28: No alerts for the micronucleus assay (Class II) | CF28: Negative | CG28: 0.0901 | CH28: Negative | CI28: 0.0395 | CW28: Negative | CX28: Negative | CY28: Inactive | CZ28: Negative | DA28: Negative | DB28: Negative | DL28: Negative | DM28: Negative | DN28: Positive | DO28: Negative | DP28: Positive | DS28: 848.086 | DT28: out of AD | DU28: 282.296 | DW28: 23.8 | DX28: maybe | DY28: 1410 | DZ28: maybe | FA28: 208.98 | FB28: MODERATE | FC28: 876.19345 | FD28: MODERATE | FE28: 47.874031 | FF28: YES | FH28: 480.95008 | FI28: MODERATE | FJ28: 186 | FK28: maybe | FL28: 482 | FM28: 373.50808 | FN28: YES | FP28: 18.6 | FQ28: Lazar | FS28: PRED | FU28: 1 | FV28: 10 | FW28: 10 | FX28: 10 | FY28: 3 | FZ28: =FU28*FV28*FW28*FX28*FY28 -> 3000 | GA28: Low (Class I) | GB28: Low (Class I) | GC28: 30 | GD28: ToxTree, Nestlé Lazar, QSAR ToolBox v 4.4 | GF28: 0.062 | GM28: This substance is authorised to be used as it is covered by the SML for FCM substance 3 and 13 as mixture of alcohols. | GR28: This substance is authorised to be used as it is covered by the SML for FCM substance 3 and 13 as mixture of alcohols. | GU28: Toxicant | GV28: MODERATE | GW28: NON-Toxicant | GX28: LOW | GY28: Not known precedent reproductive and developmental toxic potential | HE28: Not predicted | HF28: LOW | HG28: Active | HH28: GOOD | HI28: NON-active | HJ28: GOOD | HK28: Non binder, non cyclic structure | HO28: Inactive | HP28: GOOD | HQ28: Inactive | HR28: GOOD | HU28: Inactive | HV28: GOOD | HW28: Not predicted | HX28: LOW | IA28: Inactive | IB28: [Model ]Unable to perform Applicability Domain check. | IG28: --> add sentence in remark fields | IH28: no
